{
  "version": 8,
  "blockIdVersion": 11,
  "anchorX": 0,
  "anchorY": 0,
  "anchorZ": 0,
  "blocks": [
    {
      "x": -6,
      "y": -1,
      "z": -2,
      "name": "Soil_Grass_Deep"
    },
    {
      "x": -6,
      "y": -1,
      "z": -1,
      "name": "Soil_Grass_Deep"
    },
    {
      "x": -6,
      "y": -1,
      "z": 0,
      "name": "Soil_Grass_Deep"
    },
    {
      "x": -6,
      "y": -1,
      "z": 1,
      "name": "Soil_Pathway"
    },
    {
      "x": -6,
      "y": -1,
      "z": 2,
      "name": "Soil_Grass_Deep"
    },
    {
      "x": -5,
      "y": -1,
      "z": -3,
      "name": "Soil_Grass_Deep"
    },
    {
      "x": -5,
      "y": -1,
      "z": -2,
      "name": "Soil_Grass_Deep"
    },
    {
      "x": -5,
      "y": -1,
      "z": -1,
      "name": "Soil_Grass_Deep"
    },
    {
      "x": -5,
      "y": -1,
      "z": 0,
      "name": "Soil_Pathway"
    },
    {
      "x": -5,
      "y": -1,
      "z": 1,
      "name": "Soil_Grass_Deep"
    },
    {
      "x": -5,
      "y": -1,
      "z": 2,
      "name": "Soil_Grass_Deep"
    },
    {
      "x": -5,
      "y": -1,
      "z": 3,
      "name": "Soil_Grass_Deep"
    },
    {
      "x": -4,
      "y": -1,
      "z": -4,
      "name": "Soil_Grass_Deep"
    },
    {
      "x": -4,
      "y": -1,
      "z": -3,
      "name": "Soil_Grass_Deep"
    },
    {
      "x": -4,
      "y": -1,
      "z": -2,
      "name": "Soil_Grass_Deep"
    },
    {
      "x": -4,
      "y": -1,
      "z": -1,
      "name": "Soil_Pathway"
    },
    {
      "x": -4,
      "y": -1,
      "z": 0,
      "name": "Soil_Grass_Deep"
    },
    {
      "x": -4,
      "y": -1,
      "z": 1,
      "name": "Soil_Grass_Deep"
    },
    {
      "x": -4,
      "y": -1,
      "z": 2,
      "name": "Soil_Grass_Deep"
    },
    {
      "x": -4,
      "y": -1,
      "z": 3,
      "name": "Soil_Pathway"
    },
    {
      "x": -4,
      "y": -1,
      "z": 4,
      "name": "Soil_Grass_Deep"
    },
    {
      "x": -3,
      "y": -1,
      "z": -4,
      "name": "Soil_Grass_Deep"
    },
    {
      "x": -3,
      "y": -1,
      "z": -3,
      "name": "Soil_Grass_Deep"
    },
    {
      "x": -3,
      "y": -1,
      "z": -2,
      "name": "Soil_Pathway"
    },
    {
      "x": -3,
      "y": -1,
      "z": -1,
      "name": "Soil_Grass_Deep"
    },
    {
      "x": -3,
      "y": -1,
      "z": 0,
      "name": "Soil_Mud"
    },
    {
      "x": -3,
      "y": -1,
      "z": 1,
      "name": "Soil_Grass_Deep"
    },
    {
      "x": -3,
      "y": -1,
      "z": 2,
      "name": "Soil_Pathway"
    },
    {
      "x": -3,
      "y": -1,
      "z": 3,
      "name": "Soil_Grass_Deep"
    },
    {
      "x": -3,
      "y": -1,
      "z": 4,
      "name": "Soil_Grass_Deep"
    },
    {
      "x": -2,
      "y": -1,
      "z": -4,
      "name": "Soil_Grass_Deep"
    },
    {
      "x": -2,
      "y": -1,
      "z": -3,
      "name": "Soil_Pathway"
    },
    {
      "x": -2,
      "y": -1,
      "z": -2,
      "name": "Soil_Grass_Deep"
    },
    {
      "x": -2,
      "y": -1,
      "z": -1,
      "name": "Soil_Mud"
    },
    {
      "x": -2,
      "y": -1,
      "z": 0,
      "name": "Soil_Mud"
    },
    {
      "x": -2,
      "y": -1,
      "z": 1,
      "name": "Soil_Mud"
    },
    {
      "x": -2,
      "y": -1,
      "z": 2,
      "name": "Soil_Grass_Deep"
    },
    {
      "x": -2,
      "y": -1,
      "z": 3,
      "name": "Soil_Grass_Deep"
    },
    {
      "x": -2,
      "y": -1,
      "z": 4,
      "name": "Soil_Grass_Deep"
    },
    {
      "x": -1,
      "y": -1,
      "z": -4,
      "name": "Soil_Pathway"
    },
    {
      "x": -1,
      "y": -1,
      "z": -3,
      "name": "Soil_Grass_Deep"
    },
    {
      "x": -1,
      "y": -1,
      "z": -2,
      "name": "Soil_Mud"
    },
    {
      "x": -1,
      "y": -1,
      "z": -1,
      "name": "Soil_Mud"
    },
    {
      "x": -1,
      "y": -1,
      "z": 0,
      "name": "Soil_Mud"
    },
    {
      "x": -1,
      "y": -1,
      "z": 1,
      "name": "Soil_Mud"
    },
    {
      "x": -1,
      "y": -1,
      "z": 2,
      "name": "Soil_Mud"
    },
    {
      "x": -1,
      "y": -1,
      "z": 3,
      "name": "Soil_Grass_Deep"
    },
    {
      "x": -1,
      "y": -1,
      "z": 4,
      "name": "Soil_Pathway"
    },
    {
      "x": 0,
      "y": -1,
      "z": -4,
      "name": "Soil_Grass_Deep"
    },
    {
      "x": 0,
      "y": -1,
      "z": -3,
      "name": "Soil_Mud"
    },
    {
      "x": 0,
      "y": -1,
      "z": -2,
      "name": "Soil_Mud"
    },
    {
      "x": 0,
      "y": -1,
      "z": -1,
      "name": "Soil_Mud"
    },
    {
      "x": 0,
      "y": -1,
      "z": 0,
      "name": "Soil_Mud"
    },
    {
      "x": 0,
      "y": -1,
      "z": 1,
      "name": "Soil_Mud"
    },
    {
      "x": 0,
      "y": -1,
      "z": 2,
      "name": "Soil_Mud"
    },
    {
      "x": 0,
      "y": -1,
      "z": 3,
      "name": "Soil_Mud"
    },
    {
      "x": 0,
      "y": -1,
      "z": 4,
      "name": "Soil_Grass_Deep"
    },
    {
      "x": 1,
      "y": -1,
      "z": -4,
      "name": "Soil_Grass_Deep"
    },
    {
      "x": 1,
      "y": -1,
      "z": -3,
      "name": "Soil_Grass_Deep"
    },
    {
      "x": 1,
      "y": -1,
      "z": -2,
      "name": "Soil_Mud"
    },
    {
      "x": 1,
      "y": -1,
      "z": -1,
      "name": "Soil_Mud"
    },
    {
      "x": 1,
      "y": -1,
      "z": 0,
      "name": "Soil_Mud"
    },
    {
      "x": 1,
      "y": -1,
      "z": 1,
      "name": "Soil_Mud"
    },
    {
      "x": 1,
      "y": -1,
      "z": 2,
      "name": "Soil_Mud"
    },
    {
      "x": 1,
      "y": -1,
      "z": 3,
      "name": "Soil_Grass_Deep"
    },
    {
      "x": 1,
      "y": -1,
      "z": 4,
      "name": "Soil_Grass_Deep"
    },
    {
      "x": 2,
      "y": -1,
      "z": -4,
      "name": "Soil_Grass_Deep"
    },
    {
      "x": 2,
      "y": -1,
      "z": -3,
      "name": "Soil_Pathway"
    },
    {
      "x": 2,
      "y": -1,
      "z": -2,
      "name": "Soil_Grass_Deep"
    },
    {
      "x": 2,
      "y": -1,
      "z": -1,
      "name": "Soil_Mud"
    },
    {
      "x": 2,
      "y": -1,
      "z": 0,
      "name": "Soil_Mud"
    },
    {
      "x": 2,
      "y": -1,
      "z": 1,
      "name": "Soil_Mud"
    },
    {
      "x": 2,
      "y": -1,
      "z": 2,
      "name": "Soil_Grass_Deep"
    },
    {
      "x": 2,
      "y": -1,
      "z": 3,
      "name": "Soil_Grass_Deep"
    },
    {
      "x": 2,
      "y": -1,
      "z": 4,
      "name": "Soil_Grass_Deep"
    },
    {
      "x": 3,
      "y": -1,
      "z": -4,
      "name": "Soil_Pathway"
    },
    {
      "x": 3,
      "y": -1,
      "z": -3,
      "name": "Soil_Grass_Deep"
    },
    {
      "x": 3,
      "y": -1,
      "z": -2,
      "name": "Soil_Grass_Deep"
    },
    {
      "x": 3,
      "y": -1,
      "z": -1,
      "name": "Soil_Grass_Deep"
    },
    {
      "x": 3,
      "y": -1,
      "z": 0,
      "name": "Soil_Mud"
    },
    {
      "x": 3,
      "y": -1,
      "z": 1,
      "name": "Soil_Grass_Deep"
    },
    {
      "x": 3,
      "y": -1,
      "z": 2,
      "name": "Soil_Grass_Deep"
    },
    {
      "x": 3,
      "y": -1,
      "z": 3,
      "name": "Soil_Grass_Deep"
    },
    {
      "x": 3,
      "y": -1,
      "z": 4,
      "name": "Soil_Pathway"
    },
    {
      "x": 4,
      "y": -1,
      "z": -4,
      "name": "Soil_Grass_Deep"
    },
    {
      "x": 4,
      "y": -1,
      "z": -3,
      "name": "Soil_Grass_Deep"
    },
    {
      "x": 4,
      "y": -1,
      "z": -2,
      "name": "Soil_Grass_Deep"
    },
    {
      "x": 4,
      "y": -1,
      "z": -1,
      "name": "Soil_Pathway"
    },
    {
      "x": 4,
      "y": -1,
      "z": 0,
      "name": "Soil_Grass_Deep"
    },
    {
      "x": 4,
      "y": -1,
      "z": 1,
      "name": "Soil_Grass_Deep"
    },
    {
      "x": 4,
      "y": -1,
      "z": 2,
      "name": "Soil_Grass_Deep"
    },
    {
      "x": 4,
      "y": -1,
      "z": 3,
      "name": "Soil_Pathway"
    },
    {
      "x": 4,
      "y": -1,
      "z": 4,
      "name": "Soil_Grass_Deep"
    },
    {
      "x": 5,
      "y": -1,
      "z": -3,
      "name": "Soil_Grass_Deep"
    },
    {
      "x": 5,
      "y": -1,
      "z": -2,
      "name": "Soil_Pathway"
    },
    {
      "x": 5,
      "y": -1,
      "z": -1,
      "name": "Soil_Grass_Deep"
    },
    {
      "x": 5,
      "y": -1,
      "z": 0,
      "name": "Soil_Grass_Deep"
    },
    {
      "x": 5,
      "y": -1,
      "z": 1,
      "name": "Soil_Grass_Deep"
    },
    {
      "x": 5,
      "y": -1,
      "z": 2,
      "name": "Soil_Pathway"
    },
    {
      "x": 5,
      "y": -1,
      "z": 3,
      "name": "Soil_Grass_Deep"
    },
    {
      "x": 6,
      "y": -1,
      "z": -2,
      "name": "Soil_Grass_Deep"
    },
    {
      "x": 6,
      "y": -1,
      "z": -1,
      "name": "Soil_Grass_Deep"
    },
    {
      "x": 6,
      "y": -1,
      "z": 0,
      "name": "Soil_Grass_Deep"
    },
    {
      "x": 6,
      "y": -1,
      "z": 1,
      "name": "Soil_Pathway"
    },
    {
      "x": 6,
      "y": -1,
      "z": 2,
      "name": "Soil_Grass_Deep"
    },
    {
      "x": -4,
      "y": 0,
      "z": -2,
      "name": "Wood_Jungle_Roots"
    },
    {
      "x": -4,
      "y": 0,
      "z": 2,
      "name": "Wood_Banyan_Roots"
    },
    {
      "x": -4,
      "y": 1,
      "z": -2,
      "name": "Wood_Jungle_Roots"
    },
    {
      "x": -4,
      "y": 1,
      "z": 2,
      "name": "Wood_Banyan_Roots"
    },
    {
      "x": -4,
      "y": 2,
      "z": -2,
      "name": "Wood_Jungle_Roots"
    },
    {
      "x": -4,
      "y": 2,
      "z": 2,
      "name": "Wood_Banyan_Roots"
    },
    {
      "x": -4,
      "y": 3,
      "z": -2,
      "name": "Wood_Jungle_Roots"
    },
    {
      "x": -4,
      "y": 3,
      "z": 2,
      "name": "Wood_Banyan_Roots"
    },
    {
      "x": -3,
      "y": 0,
      "z": -2,
      "name": "Wood_Jungle_Roots"
    },
    {
      "x": -3,
      "y": 0,
      "z": 2,
      "name": "Wood_Banyan_Roots"
    },
    {
      "x": -3,
      "y": 1,
      "z": -2,
      "name": "Wood_Jungle_Roots"
    },
    {
      "x": -3,
      "y": 1,
      "z": 2,
      "name": "Wood_Banyan_Roots"
    },
    {
      "x": -3,
      "y": 2,
      "z": -2,
      "name": "Wood_Jungle_Roots"
    },
    {
      "x": -3,
      "y": 2,
      "z": 2,
      "name": "Wood_Banyan_Roots"
    },
    {
      "x": -3,
      "y": 3,
      "z": -2,
      "name": "Wood_Jungle_Roots"
    },
    {
      "x": -3,
      "y": 3,
      "z": 2,
      "name": "Wood_Banyan_Roots"
    },
    {
      "x": 3,
      "y": 0,
      "z": -2,
      "name": "Wood_Jungle_Roots"
    },
    {
      "x": 3,
      "y": 0,
      "z": 2,
      "name": "Wood_Banyan_Roots"
    },
    {
      "x": 3,
      "y": 1,
      "z": -2,
      "name": "Wood_Jungle_Roots"
    },
    {
      "x": 3,
      "y": 1,
      "z": 2,
      "name": "Wood_Banyan_Roots"
    },
    {
      "x": 3,
      "y": 2,
      "z": -2,
      "name": "Wood_Jungle_Roots"
    },
    {
      "x": 3,
      "y": 2,
      "z": 2,
      "name": "Wood_Banyan_Roots"
    },
    {
      "x": 3,
      "y": 3,
      "z": -2,
      "name": "Wood_Jungle_Roots"
    },
    {
      "x": 3,
      "y": 3,
      "z": 2,
      "name": "Wood_Banyan_Roots"
    },
    {
      "x": 4,
      "y": 0,
      "z": -2,
      "name": "Wood_Jungle_Roots"
    },
    {
      "x": 4,
      "y": 0,
      "z": 2,
      "name": "Wood_Banyan_Roots"
    },
    {
      "x": 4,
      "y": 1,
      "z": -2,
      "name": "Wood_Jungle_Roots"
    },
    {
      "x": 4,
      "y": 1,
      "z": 2,
      "name": "Wood_Banyan_Roots"
    },
    {
      "x": 4,
      "y": 2,
      "z": -2,
      "name": "Wood_Jungle_Roots"
    },
    {
      "x": 4,
      "y": 2,
      "z": 2,
      "name": "Wood_Banyan_Roots"
    },
    {
      "x": 4,
      "y": 3,
      "z": -2,
      "name": "Wood_Jungle_Roots"
    },
    {
      "x": 4,
      "y": 3,
      "z": 2,
      "name": "Wood_Banyan_Roots"
    },
    {
      "x": -3,
      "y": 4,
      "z": -2,
      "name": "Wood_Jungle_Roots"
    },
    {
      "x": -3,
      "y": 4,
      "z": 2,
      "name": "Wood_Banyan_Roots"
    },
    {
      "x": -3,
      "y": 3,
      "z": 0,
      "name": "Plant_Vine_Liana"
    },
    {
      "x": -2,
      "y": 4,
      "z": -2,
      "name": "Wood_Jungle_Roots"
    },
    {
      "x": -2,
      "y": 4,
      "z": 2,
      "name": "Wood_Banyan_Roots"
    },
    {
      "x": -1,
      "y": 4,
      "z": -2,
      "name": "Wood_Jungle_Roots"
    },
    {
      "x": -1,
      "y": 4,
      "z": 2,
      "name": "Wood_Banyan_Roots"
    },
    {
      "x": -1,
      "y": 3,
      "z": 0,
      "name": "Plant_Vine_Liana"
    },
    {
      "x": 0,
      "y": 4,
      "z": -2,
      "name": "Wood_Jungle_Roots"
    },
    {
      "x": 0,
      "y": 4,
      "z": 2,
      "name": "Wood_Banyan_Roots"
    },
    {
      "x": 1,
      "y": 4,
      "z": -2,
      "name": "Wood_Jungle_Roots"
    },
    {
      "x": 1,
      "y": 4,
      "z": 2,
      "name": "Wood_Banyan_Roots"
    },
    {
      "x": 1,
      "y": 3,
      "z": 0,
      "name": "Plant_Vine_Liana"
    },
    {
      "x": 2,
      "y": 4,
      "z": -2,
      "name": "Wood_Jungle_Roots"
    },
    {
      "x": 2,
      "y": 4,
      "z": 2,
      "name": "Wood_Banyan_Roots"
    },
    {
      "x": 3,
      "y": 4,
      "z": -2,
      "name": "Wood_Jungle_Roots"
    },
    {
      "x": 3,
      "y": 4,
      "z": 2,
      "name": "Wood_Banyan_Roots"
    },
    {
      "x": 3,
      "y": 3,
      "z": 0,
      "name": "Plant_Vine_Liana"
    },
    {
      "x": 0,
      "y": 0,
      "z": 0,
      "name": "Deco_Nest"
    },
    {
      "x": -1,
      "y": 0,
      "z": 1,
      "name": "Deco_Scarak_Eggsacks"
    },
    {
      "x": 1,
      "y": 0,
      "z": -1,
      "name": "Deco_Bone_Pile"
    },
    {
      "x": -3,
      "y": 0,
      "z": 3,
      "name": "Deco_Bone_Ribs",
      "rotation": 1
    },
    {
      "x": 3,
      "y": 0,
      "z": 3,
      "name": "Plant_Fern_Tall"
    },
    {
      "x": 0,
      "y": 0,
      "z": 2,
      "name": "Block_Spawner_Block",
      "rotation": 2,
      "components": {
        "Components": {
          "BlockSpawner": {
            "BlockSpawnerId": "Zone4_Encounters_Tier1"
          }
        }
      }
    }
  ]
}
